Workbook

Sheet Lists
B2: Yes
B3: Not Applicable
B4: No
B6: New
B7: Not Applicable
B8: Existing
B10: Male
B11: Female
B13: Married
B14: Unmarried
B16: Secondary
B17: Higher secondary
... B149: Unsecured

Sheet Customer Details
B1: INSTRUCTION - ENTER DATA ONLY AS INPUT IN LIGHT GREY SPACES & LIGHT GREEN DROP DOWNS
B3: Customer Details | E3: Date of Loan Application | F3: 45909
B4: Customer Name | C4: Fedilia Perriera | E4: Branch | F4: Dilli
B5: Gender | C5: Female
B6: Date of Birth | C6: 32643
B7: Age | C7: =(TODAY()-C6)/365 -> 36.375342
B8: Marital Status | C8: Unmarried
B9: Qualification | C9: Graduate
B10: No. of Family Members staying together including customer | C10: 2
B11: No. of Earning member in the family including customer | C11: 1
B12: Existing Customer | C12: No
B13: If yes, since which year | C13: 2020
B14: Residence Ownership | C14: Owned
B15: Residence Location | C15: Dili
B16: Residence Stay Vintage (Years) | C16: 36
B17: Does Customer have more than one income source | C17: No
B18: Does customer have any live loan | C18: No
B19: Did the customer have any loan in last 2 years | C19: No
B20: 0 DPD in last 6 months, never been in 30 DPD in last 12 months and currently not delinquent | C20: No | E20: (Either C20, C21, C22 will be TRUE, so If this condition is true put "YES", else "NO")
B21: Never 30 DPD in last 6 months, never been in 60 DPD in last 12 months and currently not delinquent | C21: No | E21: (Either C20, C21, C22 will be TRUE, so If this condition is true put "YES", else "NO")
B22: Currently No loans | C22: No | E22: (Either C20, C21, C22 will be TRUE, so If this condition is true put "No", else "Yes")
B24: Co-Applicant or 3rd Party Guatantor Details
B25: Name | C25: Maria
B26: Gender | C26: Female
B27: Date of Birth | C27: 33311
B28: Marital Status | C28: Unmarried
B29: Qualification | C29: Graduate
B30: Relationship with Customer | C30: Sister
B31: Profession | C31: Not Employed
B32: Type of Business
B33: Business Sub-Segment
B34: Residence Location | C34: Dili
B35: Work Location
B36: If Salaried, then Name of company employed with
B37: If Salaried, Vinatge of current employement
B38: If Self Employed, Name of the Firm
B39: If Self Employed, Vintage of the firm
B40: Number of Years Knowing the Customer | C40: 34
B41: Level of interaction with customer | C41: Frequent (D/W/M)
B42: Gross Margin in business (sales - purchase or cost of service/production)
...

Sheet Input Sheet <=$50000
B1: INSTRUCTION - ENTER DATA ONLY AS INPUT IN LIGHT GREY SPACES
B3: Sales Memo/Cash Book
B4: Last Month -Daily | D4: Total Amount (USD.)
C5: 5th | D5: 500
C6: 15th | D6: 800
C7: 25th | D7: 600
B8: Two Months Back -Daily
C9: 5th | D9: 700
C10: 15th | D10: 500
C11: 25th | D11: 600
B12: Three Months Month -Daily
C13: 5th | D13: 700
C14: 15th | D14: 600
C15: 25th | D15: 500
C16: Average Daily Sales | D16: =AVERAGEIF(D5:D15, ">0") -> 611.11111
B18: Purchase Memo/Cash Book
B19: Last Month -Daily | D19: Total Amount (USD.)
C20: 5th | D20: 300
C21: 15th | D21: 400
C22: 25th | D22: 300
B23: Two Months Back -Daily
C24: 5th | D24: 300
C25: 15th | D25: 200
C26: 25th | D26: 400
B27: Three Months Month -Daily
C28: 5th | D28: 500
C29: 15th | D29: 400
C30: 25th | D30: 300
C31: Average Daily Purchase | D31: =AVERAGEIF(D20:D30, ">0") -> 344.44444
B33: Bank Balance
B34: Last Month -Daily | D34: Total Amount (USD)
C35: 5th | D35: 200
C36: 15th | D36: 300
C37: 25th | D37: 400
B38: Two Months Back -Daily
C39: 5th | D39: 500
C40: 15th | D40: 400
C41: 25th | D41: 300
B42: Three Months Month -Daily
C43: 5th | D43: 300
...

Sheet Output Sheet <=$50000
C1: NO DATA ENTRY TO BE DONE IN THIS SHEET
C3: All Cash Inflow | E3: Customer Cash Flow | F3: Co Applicant/ Guarantor Cash Flow | H3: Frequency | I3: ='Input Sheet <=$50000'!B63 -> Sales Daily (USD) | J3: ='Input Sheet <=$50000'!B64 -> Sales Weekly (USD) | K3: ='Input Sheet <=$50000'!B65 -> Sales Monthly (USD)
E4: USD | F4: USD | H4: Monthly Sales Average | I4: ='Input Sheet <=$50000'!D63 -> 13000 | J4: ='Input Sheet <=$50000'!D64 -> 12000 | K4: ='Input Sheet <=$50000'!D65 -> 10000
C5: Business Income | E5: =IFERROR(IF(I5<MIN(I4:K4,L11),MIN(I4:K4,L11),I5),0) -> 15888.889 | F5: ='Input Sheet <=$50000'!E65 -> 0 | H5: Average Sales as per Register | I5: =IFERROR('Input Sheet <=$50000'!D16*('Input Sheet <=$50000'!C62-('Input Sheet <=$50000'!C61*'Input Sheet <=$50000'!C67)),0) -> 15888.889
C6: ='Input Sheet <=$50000'!B103 -> Agriculture Income (Co applicant/Guarantor) | E6: 0 | F6: ='Input Sheet <=$50000'!C103 -> 0
C7: ='Input Sheet <=$50000'!B104 -> Rental Income (Co applicant/Guarantor) | E7: 0 | F7: ='Input Sheet <=$50000'!C104 -> 0 | H7: Seasonality | I7: Low | J7: Medium | K7: High | L7: Total
C8: ='Input Sheet <=$50000'!B105 -> Salary Income(Co applicant/Guarantor) | E8: 0 | F8: ='Input Sheet <=$50000'!C105 -> 0 | H8: Sales Volume Monthly (USD) | I8: ='Input Sheet <=$50000'!C69 -> 0 | J8: ='Input Sheet <=$50000'!C71 -> 10000 | K8: ='Input Sheet <=$50000'!C70 -> 20000
C9: ='Input Sheet <=$50000'!B106 -> Allied Agri Income (Co applicant/Guarantor) | E9: 0 | F9: ='Input Sheet <=$50000'!C106 -> 0 | H9: Months (Min 0, Max 12) | I9: ='Input Sheet <=$50000'!D69 -> 0 | J9: ='Input Sheet <=$50000'!D71 -> 10 | K9: ='Input Sheet <=$50000'!D70 -> 2 | L9: =SUM(I9:K9) -> 12
C10: ='Input Sheet <=$50000'!B107 -> Other income (Interest etc) (Co applicant/Guarantor) | E10: 0 | F10: ='Input Sheet <=$50000'!C107 -> 0 | H10: Total Sales | I10: =I8*I9 -> 0 | J10: =J8*J9 -> 100000 | K10: =K8*K9 -> 40000 | L10: =SUM(I10:K10) -> 140000
B11: A | C11: Total Cash Inflow | E11: =IF(SUM(E6:E10)>E5,(E5*2),SUM(E5:E10)) -> 15888.889 | F11: =IF(SUM(F6:F10)>F5,(F5*2),SUM(F5:F10)) -> 0 | K11: Average | L11: =L10/SUM(I9:K9) -> 11666.667
C13: Business Cash Outlfow | E13: USD | F13: USD
C14: Purchases | E14: =IFERROR(I16,0) -> 8955.5556 | F14: ='Input Sheet <=$50000'!E78 -> 0 | H14: Frequency | I14: Daily | J14: Weekly | K14: Monthly
C15: ='Input Sheet <=$50000'!B86 -> Shop/Godown/Factory Rent | E15: ='Input Sheet <=$50000'!C86 -> 800 | F15: 0 | H15: Purchases (USD) | I15: ='Input Sheet <=$50000'!D76 -> 6500 | J15: ='Input Sheet <=$50000'!D77 -> 6000 | K15: ='Input Sheet <=$50000'!D78 -> 6000
C16: ='Input Sheet <=$50000'!B87 -> Electricity | E16: ='Input Sheet <=$50000'!C87 -> 100 | F16: 0 | H16: Total Monthly Purchase (USD) | I16: =IFERROR(IF(I17<MAX(I15:K15),MAX(I15:K15),I17),0) -> 8955.5556
C17: ='Input Sheet <=$50000'!B88 -> Staff Salary | E17: ='Input Sheet <=$50000'!C88 -> 250 | F17: 0 | H17: Average Purchase as per Register | I17: =IFERROR('Input Sheet <=$50000'!D31*('Input Sheet <=$50000'!C62-('Input Sheet <=$50000'!C61*'Input Sheet <=$50000'!C67)),0) -> 8955.5556
C18: ='Input Sheet <=$50000'!B89 -> Telephone/Mobile/Internet | E18: ='Input Sheet <=$50000'!C89 -> 25 | F18: 0
C19: ='Input Sheet <=$50000'!B90 -> Transport/Conveyance | E19: ='Input Sheet <=$50000'!C90 -> 100 | F19: 0 | L19: Guarantor
C20: ='Input Sheet <=$50000'!B91 -> Gas and Water | E20: ='Input Sheet <=$50000'!C91 -> 0 | F20: 0 | H20: Margin | I20: Actual | J20: Stated | K20: Product Margin | L20: Actual | M20: Stated
C21: ='Input Sheet <=$50000'!B92 -> Repair and Maintainence | E21: ='Input Sheet <=$50000'!C92 -> 0 | F21: 0 | H21: GP Margin | I21: =IFERROR(((E5-E14)/E5),0) -> 0.43636364 | J21: ='Customer Details'!C54 -> 0.4 | K21: =IF('Customer Details'!C48="Trading",'Input Sheet <=$50000'!D120,IF('Customer Details'!C48="Services",'Input Sheet <=$50000'!D129,IF('Customer Details'!C48="Manufacturing & Trading",AVERAGE('Input Sheet <=$50000'!D120,'Input Sheet <=$50000'!E139),IF('Customer Details'!C48="Trading & Services",AVERAGE('Input Sheet <=$50000'!D120,'Input Sheet <=$50000'!D129),IF('Customer Details'!C48="Manufacturing and Services",AVERAGE('Input Sheet <=$50000'!E139,'Input Sheet <=$50000'!D129),'Input Sheet <=$50000'!E139))))) -> 0.39487179 | L21: =IFERROR(((F5-F14)/F5),0) -> 0 | M21: ='Customer Details'!C42 -> 0
C22: ='Input Sheet <=$50000'!B93 -> Diesel for Generator | E22: ='Input Sheet <=$50000'!C93 -> 0 | F22: 0 | H22: GP Margin Considered | I22: =IFERROR(MIN(I21:K21),0) -> 0.39487179
C23: ='Input Sheet <=$50000'!B94 -> Marketing | E23: ='Input Sheet <=$50000'!C94 -> 0 | F23: 0 | H23: NP Margin | I23: =IFERROR((E31/E5),0) -> 0.35611888 | L23: =IFERROR((F31/F5),0) -> 0
C24: ='Input Sheet <=$50000'!B95 -> Labour Expense | E24: ='Input Sheet <=$50000'!C95 -> 0 | F24: 0
C25: ='Input Sheet <=$50000'!B96 -> Society Bill & Security | E25: ='Input Sheet <=$50000'!C96 -> 0 | F25: 0 | H25: Net Working Capital Days | I25: Customer | J25: Guarantor
C26: ='Input Sheet <=$50000'!B97 -> Tax | E26: ='Input Sheet <=$50000'!C97 -> 0 | F26: 0 | H26: Debtors | I26: =IFERROR((('Input Sheet <=$50000'!C72/(E5*12))*365),0) -> 0 | J26: =IFERROR(('Input Sheet <=$50000'!E71/('Output Sheet <=$50000'!F5*12))*365,0) -> 0
C27: ='Input Sheet <=$50000'!B98 -> Entertainment | E27: ='Input Sheet <=$50000'!C98 -> 0 | F27: 0 | H27: Stock | I27: =IFERROR((('Input Sheet <=$50000'!C82+'Input Sheet <=$50000'!C83)/(E14*12)*365),0) -> 135.85608 | J27: =IFERROR(('Input Sheet <=$50000'!E82+'Input Sheet <=$50000'!E83)/('Output Sheet <=$50000'!F14*12)*365,0) -> 0
C28: ='Input Sheet <=$50000'!B99 -> Other Business Expense | E28: ='Input Sheet <=$50000'!C99 -> 0 | F28: 0 | H28: Creditors | I28: =IFERROR((('Input Sheet <=$50000'!C79)/(E14*12)*365),0) -> 5.094603 | J28: =IFERROR('Input Sheet <=$50000'!E79/('Output Sheet <=$50000'!F14*12)*365,0) -> 0
B29: B | C29: Total Business Outflow | E29: =SUM(E14:E28) -> 10230.556 | F29: ='Input Sheet <=$50000'!E100+'Output Sheet <=$50000'!F14 -> 0 | H29: Net Working Capital Cycle (days) | I29: =I26+I27-I28 -> 130.76148 | J29: =J26+J27-J28 -> 0
B31: C | C31: Net Profit From Business | E31: =E5-E29 -> 5658.3333 | F31: =F5-F29 -> 0
H32: Working Capital Requirement | I32: Current Loan
B33: D | C33: Net Profit From Business to be considered Based on Lower GPM | E33: =MIN((E5-E29),(MIN(I21:K21)*E5)) -> 5658.3333 | F33: =MIN((F5-F29),(MIN(L21:M21)*F5)) -> 0 | H33: Sales Growth | I33: ='Input Sheet <=$50000'!C73 -> 0.25
H34: Annual Sales USD | I34: =(E5*12)*(1+I33) -> 238333.33
B35: E | C35: Total Monthly Surplus | E35: =MIN(E31,E33)+SUM(E6:E10) -> 5658.3333 | F35: =IF('Customer Details'!C31="Self Employed", MIN(F31,F33)+SUM(F6:F10), IF('Customer Details'!C31="Salaried", 'Input Sheet <=$50000'!C105, 0)) -> 0 | H35: =H29 -> Net Working Capital Cycle (days) | I35: =I29 -> 130.76148 | K35: =MIN(F31,F33)+SUM(F6:F10) -> 0
H36: Working capital required (USD) | I36: =I34*(I35/365) -> 85383.065
C37: Loan Eligibility | E37: USD | F37: USD | H37: Current Working Capital Funded - USD | I37: ='Input Sheet <=$50000'!C72+'Input Sheet <=$50000'!C82-'Input Sheet <=$50000'!C79 -> 38500
B38: F | C38: Total Monthly Surplus | E38: =E35 -> 5658.3333 | F38: =F35 -> 0 | H38: Additional Working Capital required USD) | I38: =IF(I36>I37,I36-I37,0) -> 46883.065
B39: G | C39: Debt Burden % | E39: ='Input Sheet <=$50000'!C142 -> 0.65 | F39: ='Input Sheet <=$50000'!C142 -> 0.65 | H39: Customer Contribution | I39: =I38*'Customer Details'!C65 -> 11720.766
B40: H | C40: Eligible EMI Debt Burden | E40: =E38*E39 -> 3677.9167 | F40: =F38*F39 -> 0 | H40: Additional Working Capital Funding Required | I40: =I38-I39 -> 35162.298
B41: I | C41: Existing Loan EMI (Personal + Business) + OD CC Interest | E41: ='Customer Details'!J108 -> 0 | F41: ='Customer Details'!J114 -> 0 | H41: Actual Customer Margin | I41: =(I38-E56)/I38 -> 0.57340673
B42: J | C42: Balance Surplus for new loan | E42: =E40-E41 -> 3677.9167 | F42: =F40-F41 -> 0
B43: K | C43: Customer Affordable EMI | E43: ='Customer Details'!C67 -> 1000 | F43: =E43 -> 1000 | H43: Capital Expenditure Requirement | I43: Current Loan
...

Sheet Expert Scorecard
B1: INSTRUCTION - ENTER DATA ONLY AS INPUT IN LIGHT GREY SPACES
B3: Rating Weightage | C3: Parameters | D3: Parameter Weightage | E3: Attribute | G3: Scoring Scale | H3: Score | I3: Comments to be input by sales Officer | K3: Rationale for Inclusion
B4: Qualitative (35%) | C4: Age | D4: 10 | E4: 21-30 years | G4: 3 | H4: =IF(OR('Customer Details'!C7=0, ISBLANK('Customer Details'!C7), 'Customer Details'!C7="", NOT(ISNUMBER('Customer Details'!C7))), 0, IF(AND('Customer Details'!C7 >= 21, 'Customer Details'!C7 < 31), 3, IF(AND('Customer Details'!C7 >= 31, 'Customer Details'!C7 < 40), 5, IF(AND('Customer Details'!C7 >= 41, 'Customer Details'!C7 < 51), 10, 7)))) -> 5 | I4: 36 | K4: Age with experience bring in maturity
E5: 31-40 years | G5: 5
E6: 41-50 years | G6: 10
E7: >50 years | G7: 7
C8: Business Vintage | D8: 10 | E8: < 5 years | G8: 2 | H8: =IF(OR('Customer Details'!C50=0, ISBLANK('Customer Details'!C50), 'Customer Details'!C50="", NOT(ISNUMBER('Customer Details'!C50))), 0,IF('Customer Details'!C50<5, 2, IF(AND('Customer Details'!C50>=5,'Customer Details'!C50<11), 5, IF(AND('Customer Details'!C50>=11,'Customer Details'!C50<16), 8, 10)))) -> 5 | I8: 8 | K8: Higher Business vintage indicates ability to handle favorable and adverse business cycles
E9: Between 5-10years | G9: 5
E10: Between 11-15 years | G10: 8
E11: Greater than 15 years | G11: 10
C12: Shop Ownership | D12: 10 | E12: Rented | G12: 5 | H12: =IF('Customer Details'!C51="Parental",7,IF('Customer Details'!C51="Rented",5,IF('Customer Details'!C51="Owned",10,0))) -> 5 | I12: Rented | K12: Having own place means asset creation, even parental property means longer stability at the that place
E13: Owned | G13: 10
E14: Parental | G14: 7
C15: Constitution | D15: 5 | E15: Proprietorship | G15: 1 | H15: =IF('Customer Details'!C46="Proprietorship",1,IF('Customer Details'!C46="Partnership",3,IF('Customer Details'!C46="Company",5,0))) -> 1 | I15: Proprietorship | K15: More Formalised the entity, it is better. Also, more business partners the better
E16: Partnership | G16: 3
E17: Company | G17: 5
C18: Single or Multiple Income Source | D18: 10 | E18: Single Source | G18: 5 | H18: =IF('Customer Details'!C17="No",5,IF('Customer Details'!C17="Yes",10,0)) -> 5 | I18: Single of income | K18: Customer having multliple cash flow will be able handle short term liquidity issues
E19: Customer having other income | G19: 10
B20: Quantitative (65%) | C20: Debt Burden Ratio | D20: 10 | E20: <=40 | G20: 10 | H20: =IF(OR('Output Sheet <=$50000'!E58=0, ISBLANK('Output Sheet <=$50000'!E58), 'Output Sheet <=$50000'!E58="", NOT(ISNUMBER('Output Sheet <=$50000'!E58))), 0, IF(AND('Output Sheet <=$50000'!E58 > 0, 'Output Sheet <=$50000'!E58 <= 0.4), 10, IF(AND('Output Sheet <=$50000'!E58 > 0.4, 'Output Sheet <=$50000'!E58 <= 0.45), 8, IF(AND('Output Sheet <=$50000'!E58 > 0.45, 'Output Sheet <=$50000'!E58 <= 0.5), 6, 2)))) -> 10 | I20: 0.166 | K20: Lower DBR ratio means better EMII repayment capacity
E21: 41-45% | G21: 8
E22: 46-50% | G22: 6
E23: > 50% | G23: 3
C24: DSCR | D24: 10 | E24: 1.2 - 1.33 times | G24: 3 | H24: =IF(OR('Financial Analysis >$50000'!B91=0, ISBLANK('Financial Analysis >$50000'!B91), 'Financial Analysis >$50000'!B91="", NOT(ISNUMBER('Financial Analysis >$50000'!B91))), 0, IF(AND('Financial Analysis >$50000'!B91>=1.2,'Financial Analysis >$50000'!B91<=1.33), 3, IF(AND('Financial Analysis >$50000'!B91>=1.34,'Financial Analysis >$50000'!B91<=1.5), 6, IF(AND('Financial Analysis >$50000'!B91>=1.51,'Financial Analysis >$50000'!B91<=1.75), 8, IF('Financial Analysis >$50000'!B91>1.75, 10, 0))))) -> 0 | I24: NA | K24: Higher DSCR means better EMII repayment capacity
E25: Between 1.34 -1.50 times | G25: 6
E26: Between 1.51 -1.75 times | G26: 8
E27: > 1.75 times | G27: 10
C28: LTV | D28: 10 | E28: < 40% | G28: 10 | H28: =IF(OR('Customer Details'!C71=0, ISBLANK('Customer Details'!C71), 'Customer Details'!C71="", NOT(ISNUMBER('Customer Details'!C71))), 0, IF(AND('Customer Details'!C71>0,'Customer Details'!C71<40%), 10, IF(AND('Customer Details'!C71>=40%,'Customer Details'!C71<=50%), 8, IF(AND('Customer Details'!C71>=51%,'Customer Details'!C71<=60%), 6,IF(AND('Customer Details'!C71>=61%,'Customer Details'!C71<=70%), 4, 2))))) -> 10 | I28: 0.17 | K28: Lower LTV means greater equity in collateral lowering risk and better recovery rate
E29: 40-50% | G29: 8
E30: 51-60% | G30: 6
E31: 61-70% | G31: 4
E32: >70% | G32: 2
C33: Gross Margin/EBITDA | D33: 10 | E33: <=10% | G33: 3 | H33: =IF(AND(ISNUMBER('Output Sheet <=$50000'!I22), 'Output Sheet <=$50000'!I22<>0), IF('Output Sheet <=$50000'!I22> 0.3, 10, IF(AND('Output Sheet <=$50000'!I22>=0.21,'Output Sheet <=$50000'!I22<=0.3), 8, IF(AND('Output Sheet <=$50000'!I22>=0.11,'Output Sheet <=$50000'!I22<=0.2), 5, 3))), IF(AND(ISNUMBER('Financial Analysis >$50000'!B85),'Financial Analysis >$50000'!B85<>0), IF('Financial Analysis >$50000'!B85> 0.3, 10, IF(AND('Financial Analysis >$50000'!B85>=0.21,'Financial Analysis >$50000'!B85<=0.3), 8, IF(AND('Financial Analysis >$50000'!B85>=0.11,'Financial Analysis >$50000'!B85<=0.2), 5, 3))), 0)) -> 10 | I33: 0.39 | K33: Higher gross Margin means better ability to absorb cost and credit period
E34: 11-20% | G34: 5
E35: 21-30% | G35: 8
E36: > 30% | G36: 10
C37: Working Capital Cycle | D37: 10 | E37: <30 days | G37: 10 | H37: =IF(AND(ISNUMBER('Output Sheet <=$50000'!I29), 'Output Sheet <=$50000'!I29<>0), IF('Output Sheet <=$50000'!I29<30, 10, IF(AND('Output Sheet <=$50000'!I29>=31,'Output Sheet <=$50000'!I29<=60), 7, IF(AND('Output Sheet <=$50000'!I29>=61,'Output Sheet <=$50000'!I29<=90), 5, 2))), IF(AND(ISNUMBER('Financial Analysis >$50000'!B89),'Financial Analysis >$50000'!B89<>0), IF('Financial Analysis >$50000'!B89<30, 10, IF(AND('Financial Analysis >$50000'!B89>=31,'Financial Analysis >$50000'!B89<=60), 7, IF(AND('Financial Analysis >$50000'!B89>=61,'Financial Analysis >$50000'!B89<=90), 5, 2))), 0)) -> 2 | I37: 131 | K37: Shorter operating cycle means better cash flow
E38: 31-60 days | G38: 7
E39: 61-90 days | G39: 5
E40: > 90 days | G40: 2
C41: Customer Margin in Transaction | D41: 10 | E41: > 40% | G41: 10 | H41: =IF(AND(ISNUMBER('Customer Details'!C72), 'Customer Details'!C72<>0), IF('Customer Details'!C72>0.4, 10, IF(AND('Customer Details'!C72>=0.36,'Customer Details'!C72<=0.4), 8, IF(AND('Customer Details'!C72>=0.31,'Customer Details'!C72<=0.35), 6, IF(AND('Customer Details'!C72>=0.25,'Customer Details'!C72<=0.3), 4, 2)))), IF(AND(ISNUMBER('Financial Analysis >$50000'!I104), 'Financial Analysis >$50000'!I104<>0), IF('Financial Analysis >$50000'!I104>0.4, 10, IF(AND('Financial Analysis >$50000'!I104>=0.36,'Financial Analysis >$50000'!I104<=0.4), 8, IF(AND('Financial Analysis >$50000'!I104>=0.31,'Financial Analysis >$50000'!I104<=0.35), 6, IF(AND('Financial Analysis >$50000'!I104>=0.25,'Financial Analysis >$50000'!I104<=0.3), 4, 2)))), 0)) -> 10 | I41: 0.57 | K41: Higher customer equity in trasaction shown skin the game
...

Sheet Financial Analysis >$50000
A1: ='Customer Details'!C45 -> Fashion Global | I1: These cells are calcuated fields. No data to be entered
F2: (All figures in USD)
A3: Profit & Loss Account | B3: Projected | C3: % Growth | D3: Actual | E3: % Growth | F3: Actual
B4: =D4+365 -> 46022 | D4: =+F4+366 -> 45657 | F4: 45291
A5: Operating Income :
A6: Sales/Receipts | C6: =+IF(D6=0,"-",B6/D6-1) -> - | E6: =+IF(F6=0,"-",D6/F6-1) -> -
A7: Sales | B7: =B6 -> 0 | C7: =+IF(D7=0,"-",B7/D7-1) -> - | D7: =D6 -> 0 | E7: =+IF(F7=0,"-",D7/F7-1) -> - | F7: =F6 -> 0
A8: Other Business Income | C8: =+IF(D8=0,"-",B8/D8-1) -> - | E8: =+IF(F8=0,"-",D8/F8-1) -> -
A9: Total Operating Income | B9: =B7+B8 -> 0 | C9: =+IF(D9=0,"-",B9/D9-1) -> - | D9: =D7+D8 -> 0 | E9: =+IF(F9=0,"-",D9/F9-1) -> - | F9: =F7+F8 -> 0
A10: Cost of Goods Sold :
A11: Purchases | C11: =+IF(D11=0,"-",B11/D11-1) -> - | E11: =+IF(F11=0,"-",D11/F11-1) -> -
A12: Direct Expenses (Wages, Overheads) | C12: =+IF(D12=0,"-",B12/D12-1) -> - | E12: =+IF(F12=0,"-",D12/F12-1) -> -
A13: Changes in Stock (Closing - Opening) | C13: =+IF(D13=0,"-",B13/D13-1) -> - | E13: =+IF(F13=0,"-",D13/F13-1) -> -
A14: Total Cost of Goods Sold | B14: =+B11+B12+B13 -> 0 | C14: =+IF(D14=0,"-",B14/D14-1) -> - | D14: =+D11+D12+D13 -> 0 | E14: =+IF(F14=0,"-",D14/F14-1) -> - | F14: =+F11+F12+F13 -> 0
A15: Indirect Expenses :
A16: General & Admin Expenses | C16: =+IF(D16=0,"-",B16/D16-1) -> - | E16: =+IF(F16=0,"-",D16/F16-1) -> -
A17: Personnel Cost | C17: =+IF(D17=0,"-",B17/D17-1) -> - | E17: =+IF(F17=0,"-",D17/F17-1) -> -
A18: Selling and Distribution Expenses | C18: =+IF(D18=0,"-",B18/D18-1) -> - | E18: =+IF(F18=0,"-",D18/F18-1) -> -
A19: Miscellaneous / Deferred Revenue Expenses written off | C19: =+IF(D19=0,"-",B19/D19-1) -> - | E19: =+IF(F19=0,"-",D19/F19-1) -> -
A20: Total Indirect Expenses | B20: =SUM(B16:B19) -> 0 | C20: =+IF(D20=0,"-",B20/D20-1) -> - | D20: =SUM(D16:D19) -> 0 | E20: =+IF(F20=0,"-",D20/F20-1) -> - | F20: =SUM(F16:F19) -> 0
A21: EBITDA | B21: =B9-B14-B20 -> 0 | C21: =+IF(D21=0,"-",B21/D21-1) -> - | D21: =D9-D14-D20 -> 0 | E21: =+IF(F21=0,"-",D21/F21-1) -> - | F21: =F9-F14-F20 -> 0
A22: Depreciation and amortisation | C22: =+IF(D22=0,"-",B22/D22-1) -> - | E22: =+IF(F22=0,"-",D22/F22-1) -> -
A23: EBIT | B23: =B21-B22 -> 0 | C23: =+IF(D23=0,"-",B23/D23-1) -> - | D23: =D21-D22 -> 0 | E23: =+IF(F23=0,"-",D23/F23-1) -> - | F23: =F21-F22 -> 0
A24: Interest and finance charges | C24: =+IF(D24=0,"-",B24/D24-1) -> - | E24: =+IF(F24=0,"-",D24/F24-1) -> -
A25: PBT (Operating) | B25: =B23-B24 -> 0 | C25: =+IF(D25=0,"-",B25/D25-1) -> - | D25: =D23-D24 -> 0 | E25: =+IF(F25=0,"-",D25/F25-1) -> - | F25: =F23-F24 -> 0
A26: Non Operating Income | C26: =+IF(D26=0,"-",B26/D26-1) -> - | E26: =+IF(F26=0,"-",D26/F26-1) -> -
A27: Non Operating Expenses | C27: =+IF(D27=0,"-",B27/D27-1) -> - | E27: =+IF(F27=0,"-",D27/F27-1) -> -
A28: Profit Before Tax | B28: =B25+B26-B27 -> 0 | C28: =+IF(D28=0,"-",B28/D28-1) -> - | D28: =D25+D26-D27 -> 0 | E28: =+IF(F28=0,"-",D28/F28-1) -> - | F28: =F25+F26-F27 -> 0
A29: Tax | C29: =+IF(D29=0,"-",B29/D29-1) -> - | E29: =+IF(F29=0,"-",D29/F29-1) -> -
A30: PAT | B30: =B28-B29 -> 0 | C30: =+IF(D30=0,"-",B30/D30-1) -> - | D30: =D28-D29 -> 0 | E30: =+IF(F30=0,"-",D30/F30-1) -> - | F30: =F28-F29 -> 0
A32: Cash Profits | B32: =B30+B22+B19 -> 0 | C32: =+IF(D32=0,"-",B32/D32-1) -> - | D32: =D30+D22+D19 -> 0 | E32: =+IF(F32=0,"-",D32/F32-1) -> - | F32: =F30+F22+F19 -> 0
A34: Balance Sheet : | B34: =B3 -> Projected | C34: Growth % | D34: =D3 -> Actual | E34: Growth % | F34: =F3 -> Actual
B35: =+B4 -> 46022 | D35: =+D4 -> 45657 | F35: =+F4 -> 45291
A36: Equity Share Capital :
A37: Equity and Preference Share Capital | C37: =+IF(D37=0,"-",B37/D37-1) -> - | E37: =+IF(F37=0,"-",D37/F37-1) -> -
A38: Quasi Equity (Promoter Loans not entailing repayment) | C38: =+IF(D38=0,"-",B38/D38-1) -> - | E38: =+IF(F38=0,"-",D38/F38-1) -> -
A39: General Reserve, Share Premium Reserve and Other reserves | C39: =+IF(D39=0,"-",B39/D39-1) -> - | E39: =+IF(F39=0,"-",D39/F39-1) -> -
A40: Net worth | B40: =B37+B38+B39 -> 0 | C40: =+IF(D40=0,"-",B40/D40-1) -> - | D40: =D37+D38+D39 -> 0 | E40: =+IF(F40=0,"-",D40/F40-1) -> - | F40: =F37+F38+F39 -> 0
A41: Revaluation Reserve | C41: =+IF(D41=0,"-",B41/D41-1) -> - | E41: =+IF(F41=0,"-",D41/F41-1) -> -
A42: Net Intangibles (Goodwill / Patents / Trademark) | C42: =+IF(D42=0,"-",B42/D42-1) -> - | E42: =+IF(F42=0,"-",D42/F42-1) -> -
...

Sheet Bank Analysis >$50000
G1: (All figures in $) | J1: These cells are calcuated fields. No data to be entered | V1: (All figures in $)
A2: Bank Name | F2: ABB | G2: =AVERAGE(B6:G11) -> 0 | I2: Banking Credits fort last 12 months | W2: Concentration
A3: Account Type | C3: Savings/Current | I3: Month | J3: =+EDATE(K3,-1) -> 45320 | K3: =+EDATE(L3,-1) -> 45351 | L3: =+EDATE(M3,-1) -> 45381 | M3: =+EDATE(N3,-1) -> 45412 | N3: =+EDATE(O3,-1) -> 45442 | O3: =+EDATE(P3,-1) -> 45473 | P3: =+EDATE(Q3,-1) -> 45503 | Q3: =+EDATE(R3,-1) -> 45534 | ... T3: =+EDATE(U3,-1) -> 45626 | U3: 45657
I4: Bank - 1 (Credit ) | J4: 0 | K4: 0 | L4: 0 | M4: 0 | N4: 0 | O4: 0 | P4: 0 | Q4: 0 | R4: 0 | S4: 0 | T4: 0 | U4: 0 | V4: =SUM(J4:U4) -> 0
A5: Dates | B5: =+P3 -> 45503 | C5: =+Q3 -> 45534 | D5: =+R3 -> 45565 | E5: =+S3 -> 45595 | F5: =+T3 -> 45626 | G5: =+U3 -> 45657 | I5: Bank -2 (Credit ) | J5: 0 | K5: 0 | L5: 0 | M5: 0 | N5: 0 | O5: 0 | P5: 0 | Q5: 0 | R5: 0 | S5: 0 | T5: 0 | U5: 0 | V5: =SUM(J5:U5) -> 0
A6: 5th | B6: 0 | C6: 0 | D6: 0 | E6: 0 | F6: 0 | G6: 0 | I6: Total Credits | J6: =SUM(J4:J5) -> 0 | K6: =SUM(K4:K5) -> 0 | L6: =SUM(L4:L5) -> 0 | M6: =SUM(M4:M5) -> 0 | N6: =SUM(N4:N5) -> 0 | O6: =SUM(O4:O5) -> 0 | P6: =SUM(P4:P5) -> 0 | Q6: =SUM(Q4:Q5) -> 0 | ... U6: =SUM(U4:U5) -> 0 | V6: =SUM(J6:U6) -> 0
A7: 10th | B7: 0 | C7: 0 | D7: 0 | E7: 0 | F7: 0 | G7: 0
A8: 15th | B8: 0 | C8: 0 | D8: 0 | E8: 0 | F8: 0 | G8: 0 | I8: Note
A9: 20th | B9: 0 | C9: 0 | D9: 0 | E9: 0 | F9: 0 | G9: 0 | I9: Please input end of month credit balances including bank transfers, cash deposit but excluding contra entries
A10: 25th | B10: 0 | C10: 0 | D10: 0 | E10: 0 | F10: 0 | G10: 0
A11: Last Day of the month | B11: 0 | C11: 0 | D11: 0 | E11: 0 | F11: 0 | G11: 0
A13: Bank Name | F13: ABB | G13: =AVERAGE(B16:G21) -> 0
A14: Account Type | C14: Savings/Current | I14: Total Credits (Amt) $ | J14: =SUM(J6:U6) -> 0
A15: Dates | B15: =+P3 -> 45503 | C15: =+Q3 -> 45534 | D15: =+R3 -> 45565 | E15: =+S3 -> 45595 | F15: =+T3 -> 45626 | G15: =+U3 -> 45657 | I15: Sales Through Put in Bank | J15: =J14/'Financial Analysis >$50000'!D7 -> #DIV/0!
A16: 5th | B16: 0 | C16: 0 | D16: 0 | E16: 0 | F16: 0 | G16: 0
A17: 10th | B17: 0 | C17: 0 | D17: 0 | E17: 0 | F17: 0 | G17: 0
A18: 15th | B18: 0 | C18: 0 | D18: 0 | E18: 0 | F18: 0 | G18: 0
A19: 20th | B19: 0 | C19: 0 | D19: 0 | E19: 0 | F19: 0 | G19: 0
A20: 25th | B20: 0 | C20: 0 | D20: 0 | E20: 0 | F20: 0 | G20: 0
A21: Last Day of the month | B21: 0 | C21: 0 | D21: 0 | E21: 0 | F21: 0 | G21: 0
A23: Note
A24: Please input end of Day balances for the last 6 months from the operating bank accounts for specific dates to understand average bank balance for the period

Sheet Credit App Memo
B1: INSTRUCTION - ENTER DATA ONLY AS INPUT IN LIGHT GREY SPACES & LIGHT GREEN DROP DOWNS
B3: Customer Details
B4: Date of Proposal | C4: ='Customer Details'!F3 -> 45909 | E4: Deviation Code | F4: Norm | G4: Deviation
B5: Branch | C5: ='Customer Details'!F4 -> Dilli | E5: D1 | F5: Business Vintage | G5: Secured – less than 1 years Unsecured - Less than 3 years
B6: Customer Name | C6: ='Customer Details'!C4 -> Fedilia Perriera | E6: D2 | F6: Business Stability | G6: Less than 1year
B7: Purpose for Borrowing | C7: ='Customer Details'!C63 -> Working Capital | E7: D3 | F7: Age | G7: Upto 2 years (+/-)
B8: Business Segment | C8: ='Customer Details'!C48 -> Trading | E8: D4 | F8: Loan to Value | G8: +5%
B9: Busness Sub-Segment | C9: ='Customer Details'!C49 -> Garments | E9: D5 | F9: Debt Burden Ratio <$ 50000 | G9: +5%
B10: Current Bankers | C10: ='Customer Details'!C84 -> Mandiri | E10: D6 | F10: Expert Score | G10: High/Highest Risk
B11: Type of Facility offered | C11: Term Loan | E11: D7 | F11: 3rd party Guarantor | G11: Waiver of 3rd party guarantee
B12: Loan Amount Approved | C12: ='Customer Details'!C69 -> 20000 | E12: D8 | F12: Repayment track | G12: <90 DPD
B13: Loan Term in Months | C13: ='Customer Details'!C60 -> 24 | E13: D9 | F13: DSCR Loans > $50000 | G13: Upto 1.25 times
B14: Interest Rate | C14: ='Customer Details'!C61 -> 0.12 | E14: D10 | F14: TOL/TNW Loans > $50000 | G14: Upto 4 times
B15: Processing Fee | C15: ='Customer Details'!C62 -> 0 | E15: D11 | F15: Current Ratio loans > $50000 | G15: 1.25
B16: 3rd Party Guarantor present | C16: No | E16: D12 | F16: Financial and bank statements Loans > $50000 | G16: Not Available
B17: 3rd Party Guarantor income good to cover the EMI in case of default | C17: Not Applicable | E17: D13 | F17: Property type | G17: Industrial
B18: Supplier Reference | C18: ='Customer Details'!C128 -> Positive
B19: Buyer Refernce (B2B) | C19: ='Customer Details'!C141 -> 0
B20: CreditRisk Score | C20: {='Expert Scorecard'!I49:J49} -> High Risk | D20: 0
B21: DBR % | C21: ='Output Sheet <=$50000'!E58 -> 0.16638635
B22: Any current or past loans overdue | C22: No
B23: Total Value of Assets and Investment (USD) | C23: ='Customer Details'!C81+'Customer Details'!F81+'Customer Details'!C87+'Customer Details'!F87+'Customer Details'!C95+'Customer Details'!F95+'Customer Details'!C101+'Customer Details'!F101 -> 89000
B24: Asset and Investment Coverage over Loan Amount (Times) | C24: =C23/'Customer Details'!C69 -> 4.45
B25: Any policy Deviation | C25: No
B26: Deviation Code
B27: Reason and Mitigant for Deviation | C27: Low DBR, mainly cash business,strong reference, vintage business
B31: Qualitative Aspects to be filled up by the assessor
B32: Promoter/Entepreneur | C32: Customer is a graduate by qualifcation is running the garments business for 8 years at the same shop which is rented. . Earlier, she was working in a department shop as a sales person
B33: Business Activity | C33: Fashion Global is ladies garment shop. It is located in Dili in rented 700 sft. space. Most of the products are purchased from credit of 7 days. Sales is mainoy on cash. Applicant is full time involved with this business. One full time staff is employed in the shop. Sister also supports in Business
B34: Market and Demand | C34: There is very good demand of ladies garment in Dili. She has a lot of repeat customers who come to purchase ladies garments
B35: Cash Flow | C35: Cash flow is supporting of loan amount USD 20000. She is putting in an equity of $26000 herself for a sale growth of 25%
B36: Guanrator and References | C36: there is no guarnator in the transaction and customer providing property which is jointly owned by sister who will be the co-applicant
B37: End Use | C37: Funding is required for purchasing more tyre stock. heexpects sales upside of 20% annualised and has space to additional stock
B38: Recommendation | C38: We would recommend a loan of USD 20000 for 2 years as she is good customer having comfortable cash flow, good business vintage and positve reference checks
B41: Approver Comments
B42: Observations | C42: There is a genuine business end use. The sale growth assumptions are resonable. Cash flow is supportive. Postive reference checks and residential property as collateral
B43: Decision | C43: Approve
